Workbook

Sheet Read Me
A1: Restaurant Financial Model - Template
A2: Part of the Restaurant Feasibility Toolkit · github.com/thomasgilodi-design/restaurant-feasibility-toolkit
A4: This template reproduces the structure of the financial model I built for my own restaurant venture,
A5: with all figures replaced by illustrative examples. It models a mid-size full-service restaurant in France.
A7: TABS, IN READING ORDER
A8: Assumptions - every hypothesis in one place: baskets & customers per daypart, weekly pattern, ramp-up, costs, payroll.
A9: Revenue - the revenue equation: basket × customers × weekly pattern × operating calendar, plus Year-1 monthly ramp-up.
A10: PnL - 4-year profit & loss down to net income and cash flow after debt service.
A11: Investment - opening needs (capex, key money, fees, working capital, cash reserve) and the funding plan.
A12: Loan - full monthly amortisation table, with an interest-only deferral period.
A13: BreakEven - break-even revenue and covers at four rent scenarios: test locations BEFORE signing.
A14: KPIs - sanity-check dashboard against industry benchmarks.
... A27: Example figures only - a method, not a promise. Author: Thomas Gilodi, 2026 - MIT License.

Sheet Assumptions
A1: Assumptions | C1: Blue cells = inputs. Example values - replace with your own.
A3: REVENUE DRIVERS - PER DAYPART
B4: Lunch | C4: Dinner | D4: Delivery
A5: Average basket (incl. VAT) | B5: 24 | C5: 42 | D5: 26
A6: Average VAT rate | B6: 0.11 | C6: 0.14 | D6: 0.1 | E6: 10% food, 20% alcohol - weight by drinks share of each daypart
A7: Average basket (excl. VAT) | B7: =B5/(1+B6) -> 21.621622 | C7: =C5/(1+C6) -> 36.842105 | D7: =D5/(1+D6) -> 23.636364
A8: Customers / standard day (cruise speed) | B8: 40 | C8: 60 | D8: 12 | E8: A realistic full day once established - not your best day ever
A10: WEEKLY PATTERN (coefficient vs a standard day; 0 = closed)
B11: Lunch | C11: Dinner | D11: Delivery
A12: Monday | B12: 0.8 | C12: 0.8 | D12: 0.8
A13: Tuesday | B13: 0.8 | C13: 0.8 | D13: 0.8
A14: Wednesday | B14: 1 | C14: 1 | D14: 1
A15: Thursday | B15: 1 | C15: 1.2 | D15: 1
A16: Friday | B16: 1.2 | C16: 1.5 | D16: 1.2
A17: Saturday | B17: 1.2 | C17: 1.5 | D17: 0.8
A18: Sunday | B18: 0 | C18: 0 | D18: 0
A19: Weekly index (standard days / week) | B19: =SUM(B12:B18) -> 6 | C19: =SUM(C12:C18) -> 6.8 | D19: =SUM(D12:D18) -> 5.6
A21: OPERATING CALENDAR
A22: Weeks per month | B22: 4.33
A23: Months of operation / year | B23: 10.5 | C23: Allows for annual closure, holidays and dead weeks
A25: YEAR 1 RAMP-UP (% below cruise speed, by month)
B26: M1 | C26: M2 | D26: M3 | E26: M4 | F26: M5 | G26: M6 | H26: M7 | I26: M8 | J26: M9 | K26: M10 | L26: M11 | M26: M12
A27: Ramp-up coefficient | B27: -0.5 | C27: -0.4 | D27: -0.35 | E27: -0.3 | F27: -0.25 | G27: -0.2 | H27: -0.15 | I27: -0.1 | J27: -0.1 | K27: -0.05 | L27: -0.05 | M27: 0
A29: ANNUAL REVENUE GROWTH (after Year 1)
B30: Year 2 | C30: Year 3 | D30: Year 4
A31: Growth vs previous year | B31: 0.1 | C31: 0.06 | D31: 0.04
A33: DIRECT COSTS (% of revenue excl. VAT)
A34: Food & beverage cost | B34: 0.27 | C34: Benchmark: 25–32%
A35: Packaging | B35: 0.01 | C35: Mostly delivery/takeaway
A36: Cleaning products | B36: 0.01
A37: Dishware & smallware renewal | B37: 0.01
A39: OPERATING COSTS (annual, Year 1 basis)
A40: Rent & charges | B40: 60000 | C40: Test other levels in the BreakEven tab before signing
A41: Energy | B41: 6000
A42: Maintenance | B42: 2000
A43: Marketing | B43: 18000
A44: Software & POS | B44: 2500
A45: Small equipment | B45: 3000
A46: Bank & insurance | B46: 3000
A47: Legal | B47: 2000
...

Sheet Revenue
A1: Revenue Build - from basket to annual revenue
A3: DAILY REVENUE AT CRUISE SPEED
B4: Lunch | C4: Dinner | D4: Delivery | E4: TOTAL
A5: Average basket (excl. VAT) | B5: =Assumptions!B7 -> 21.621622 | C5: =Assumptions!C7 -> 36.842105 | D5: =Assumptions!D7 -> 23.636364
A6: Customers / standard day | B6: =Assumptions!B8 -> 40 | C6: =Assumptions!C8 -> 60 | D6: =Assumptions!D8 -> 12
A7: Revenue / standard day | B7: =B5*B6 -> 864.86486 | C7: =C5*C6 -> 2210.5263 | D7: =D5*D6 -> 283.63636 | E7: =SUM(B7:D7) -> 3359.0275
A9: WEEKLY, MONTHLY, ANNUAL - CRUISE SPEED
A10: Weekly index (from weekly pattern) | B10: =Assumptions!B19 -> 6 | C10: =Assumptions!C19 -> 6.8 | D10: =Assumptions!D19 -> 5.6
A11: Revenue / week | B11: =B7*B10 -> 5189.1892 | C11: =C7*C10 -> 15031.579 | D11: =D7*D10 -> 1588.3636 | E11: =SUM(B11:D11) -> 21809.132
A12: Revenue / month | B12: =B11*Assumptions!$B$22 -> 22469.189 | C12: =C11*Assumptions!$B$22 -> 65086.737 | D12: =D11*Assumptions!$B$22 -> 6877.6145 | E12: =SUM(B12:D12) -> 94433.541
A13: Revenue / year (cruise speed) | B13: =B12*Assumptions!$B$23 -> 235926.49 | C13: =C12*Assumptions!$B$23 -> 683410.74 | D13: =D12*Assumptions!$B$23 -> 72214.953 | E13: =SUM(B13:D13) -> 991552.18
A15: YEAR 1 - MONTHLY RAMP-UP
B16: M1 | C16: M2 | D16: M3 | E16: M4 | F16: M5 | G16: M6 | H16: M7 | I16: M8 | J16: M9 | K16: M10 | L16: M11 | M16: M12 | N16: TOTAL
A17: Ramp-up coefficient | B17: =Assumptions!B27 -> -0.5 | C17: =Assumptions!C27 -> -0.4 | D17: =Assumptions!D27 -> -0.35 | E17: =Assumptions!E27 -> -0.3 | F17: =Assumptions!F27 -> -0.25 | G17: =Assumptions!G27 -> -0.2 | H17: =Assumptions!H27 -> -0.15 | I17: =Assumptions!I27 -> -0.1 | ... M17: =Assumptions!M27 -> 0
A18: Lunch | B18: =$B$12*(1+B$17) -> 11234.595 | C18: =$B$12*(1+C$17) -> 13481.514 | D18: =$B$12*(1+D$17) -> 14604.973 | E18: =$B$12*(1+E$17) -> 15728.432 | F18: =$B$12*(1+F$17) -> 16851.892 | G18: =$B$12*(1+G$17) -> 17975.351 | H18: =$B$12*(1+H$17) -> 19098.811 | I18: =$B$12*(1+I$17) -> 20222.27 | ... M18: =$B$12*(1+M$17) -> 22469.189 | N18: =SUM(B18:M18) -> 214580.76
A19: Dinner | B19: =$C$12*(1+B$17) -> 32543.368 | C19: =$C$12*(1+C$17) -> 39052.042 | D19: =$C$12*(1+D$17) -> 42306.379 | E19: =$C$12*(1+E$17) -> 45560.716 | F19: =$C$12*(1+F$17) -> 48815.053 | G19: =$C$12*(1+G$17) -> 52069.389 | H19: =$C$12*(1+H$17) -> 55323.726 | I19: =$C$12*(1+I$17) -> 58578.063 | ... M19: =$C$12*(1+M$17) -> 65086.737 | N19: =SUM(B19:M19) -> 621578.34
A20: Delivery | B20: =$D$12*(1+B$17) -> 3438.8073 | C20: =$D$12*(1+C$17) -> 4126.5687 | D20: =$D$12*(1+D$17) -> 4470.4495 | E20: =$D$12*(1+E$17) -> 4814.3302 | F20: =$D$12*(1+F$17) -> 5158.2109 | G20: =$D$12*(1+G$17) -> 5502.0916 | H20: =$D$12*(1+H$17) -> 5845.9724 | I20: =$D$12*(1+I$17) -> 6189.8531 | ... M20: =$D$12*(1+M$17) -> 6877.6145 | N20: =SUM(B20:M20) -> 65681.219
A21: Total / month | B21: =SUM(B18:B20) -> 47216.77 | C21: =SUM(C18:C20) -> 56660.124 | D21: =SUM(D18:D20) -> 61381.801 | E21: =SUM(E18:E20) -> 66103.478 | F21: =SUM(F18:F20) -> 70825.155 | G21: =SUM(G18:G20) -> 75546.832 | H21: =SUM(H18:H20) -> 80268.509 | I21: =SUM(I18:I20) -> 84990.187 | ... M21: =SUM(M18:M20) -> 94433.541 | N21: =SUM(B21:M21) -> 901840.31
A23: Year 1 revenue (adjusted for closures) | B23: =N21*(Assumptions!$B$23/12) -> 789110.27 | D23: 12 ramped months scaled by the operating-months factor - feeds the PnL

Sheet Investment
A1: Investment Plan & Funding
A3: CAPEX - DEPRECIABLE
A4: Item | B4: Amount | C4: Depr. (years) | D4: Annual depr.
A5: Works & renovation | B5: 120000 | C5: 8 | D5: =B5/C5 -> 15000 | E5: Restaurant-experienced contractors only; +15–20% contingency in quotes
A6: Kitchen equipment | B6: 60000 | C6: 5 | D6: =B6/C6 -> 12000 | E6: Second-hand can cut this 30–50%
A7: Furniture & decor | B7: 30000 | C7: 5 | D7: =B7/C7 -> 6000
A8: Signage & visual identity | B8: 10000 | C8: 5 | D8: =B8/C8 -> 2000
A9: Subtotal capex | B9: =SUM(B5:B8) -> 220000 | D9: =SUM(D5:D8) -> 35000
A11: NON-DEPRECIABLE
A12: Key money / droit au bail / fonds de commerce | B12: 150000 | E12: Hugely variable by city and street - often the single biggest line, and negotiable
A13: Lease guarantee & deposit | B13: 15000
A14: Subtotal | B14: =SUM(B12:B13) -> 165000
A16: FEES
A17: Architect & design | B17: 12000
A18: Legal & company creation | B18: 7000
A19: Agency / brokerage fees | B19: 15000
A20: Subtotal | B20: =SUM(B17:B19) -> 34000
A22: PRE-OPENING
A23: Pre-opening marketing | B23: 10000
A24: Training & pre-opening payroll | B24: 15000
A25: Initial stock | B25: 8000
A26: Subtotal | B26: =SUM(B23:B25) -> 33000
A28: WORKING CAPITAL & CASH RESERVE
A29: Stock rotation (days) | B29: 15
A30: Customer credit (days) | B30: 2 | E30: Restaurants are paid cash - near zero
A31: Supplier credit (days) | B31: 20
A32: Working capital (BFR) | B32: =Revenue!$E$13*Assumptions!$B$34/365*B29+Revenue!$E$13/365*B30-Revenue!$E$13*Assumptions!$B$34/365*B31 -> 1765.7778 | E32: Stock + customer credit − supplier credit; often near zero or negative in restaurants
A33: Months of fixed costs held in cash reserve | B33: 4 | E33: Most failures are cash-outs during ramp-up, not bad concepts
A34: Cash reserve | B34: =B33*(Assumptions!$B$60*(1+Assumptions!$B$61)+(Assumptions!$B$40+SUM(Assumptions!$B$41:$B$48))/12) -> 153278.67
A35: Subtotal | B35: =MAX(0,B32)+B34 -> 155044.44
A37: TOTAL NEEDS | B37: =B9+B14+B20+B26+B35 -> 607044.44
A39: FUNDING PLAN
A40: Founder equity | B40: 120000 | E40: Banks expect meaningful skin in the game
A41: Love money / family & friends | B41: 40000
A42: Investor equity (business angels) | B42: 150000 | E42: Price the equity carefully - hard to undo
A43: Bank loan | B43: =Loan!$B$4 -> 280000 | E43: Set the amount in the Loan tab; keep ≤ ~50% of total funding
A44: Honour loans & subsidies | B44: 20000 | E44: Réseau Entreprendre, Initiative France… interest-free and a strong signal to banks
A45: TOTAL FUNDING | B45: =SUM(B40:B44) -> 610000
A46: Surplus / (gap) | B46: =B45-B37 -> 2955.5555 | E46: Must be ≥ 0

Sheet Loan
A1: Loan Amortisation (constant annuities, with deferral)
A3: PARAMETERS
A4: Principal | B4: 280000
A5: Annual interest rate | B5: 0.045
A6: Duration (years) | B6: 7
A7: Payments / year | B7: 12
A8: Interest-only months (deferral) | B8: 6 | C8: Negotiate a deferral so capital repayment starts after the ramp-up
A10: COMPUTED
A11: Periodic rate | B11: =B5/B7 -> 0.00375
A12: Total payments | B12: =B6*B7 -> 84
A13: Payment during deferral (interest only) | B13: =B4*B11 -> 1050
A14: Payment during amortisation | B14: =B4*B11/(1-(1+B11)^-(B12-B8)) -> 4146.9798
A15: Total interest paid | B15: =SUM(D19:D102) -> 49764.426
A17: MONTHLY TABLE
A18: # | B18: Opening balance | C18: Payment | D18: Interest | E18: Principal | F18: Closing balance | G18: Year
A19: 1 | B19: =$B$4 -> 280000 | C19: =IF(A19<=$B$8,$B$13,$B$14) -> 1050 | D19: =B19*$B$11 -> 1050 | E19: =C19-D19 -> 0 | F19: =B19-E19 -> 280000 | G19: =INT((A19-1)/12)+1 -> 1
A20: 2 | B20: =F19 -> 280000 | C20: =IF(A20<=$B$8,$B$13,$B$14) -> 1050 | D20: =B20*$B$11 -> 1050 | E20: =C20-D20 -> 0 | F20: =B20-E20 -> 280000 | G20: =INT((A20-1)/12)+1 -> 1
A21: 3 | B21: =F20 -> 280000 | C21: =IF(A21<=$B$8,$B$13,$B$14) -> 1050 | D21: =B21*$B$11 -> 1050 | E21: =C21-D21 -> 0 | F21: =B21-E21 -> 280000 | G21: =INT((A21-1)/12)+1 -> 1
A22: 4 | B22: =F21 -> 280000 | C22: =IF(A22<=$B$8,$B$13,$B$14) -> 1050 | D22: =B22*$B$11 -> 1050 | E22: =C22-D22 -> 0 | F22: =B22-E22 -> 280000 | G22: =INT((A22-1)/12)+1 -> 1
A23: 5 | B23: =F22 -> 280000 | C23: =IF(A23<=$B$8,$B$13,$B$14) -> 1050 | D23: =B23*$B$11 -> 1050 | E23: =C23-D23 -> 0 | F23: =B23-E23 -> 280000 | G23: =INT((A23-1)/12)+1 -> 1
A24: 6 | B24: =F23 -> 280000 | C24: =IF(A24<=$B$8,$B$13,$B$14) -> 1050 | D24: =B24*$B$11 -> 1050 | E24: =C24-D24 -> 0 | F24: =B24-E24 -> 280000 | G24: =INT((A24-1)/12)+1 -> 1
A25: 7 | B25: =F24 -> 280000 | C25: =IF(A25<=$B$8,$B$13,$B$14) -> 4146.9798 | D25: =B25*$B$11 -> 1050 | E25: =C25-D25 -> 3096.9798 | F25: =B25-E25 -> 276903.02 | G25: =INT((A25-1)/12)+1 -> 1
A26: 8 | B26: =F25 -> 276903.02 | C26: =IF(A26<=$B$8,$B$13,$B$14) -> 4146.9798 | D26: =B26*$B$11 -> 1038.3863 | E26: =C26-D26 -> 3108.5935 | F26: =B26-E26 -> 273794.43 | G26: =INT((A26-1)/12)+1 -> 1
A27: 9 | B27: =F26 -> 273794.43 | C27: =IF(A27<=$B$8,$B$13,$B$14) -> 4146.9798 | D27: =B27*$B$11 -> 1026.7291 | E27: =C27-D27 -> 3120.2507 | F27: =B27-E27 -> 270674.18 | G27: =INT((A27-1)/12)+1 -> 1
A28: 10 | B28: =F27 -> 270674.18 | C28: =IF(A28<=$B$8,$B$13,$B$14) -> 4146.9798 | D28: =B28*$B$11 -> 1015.0282 | E28: =C28-D28 -> 3131.9517 | F28: =B28-E28 -> 267542.22 | G28: =INT((A28-1)/12)+1 -> 1
A29: 11 | B29: =F28 -> 267542.22 | C29: =IF(A29<=$B$8,$B$13,$B$14) -> 4146.9798 | D29: =B29*$B$11 -> 1003.2833 | E29: =C29-D29 -> 3143.6965 | F29: =B29-E29 -> 264398.53 | G29: =INT((A29-1)/12)+1 -> 1
A30: 12 | B30: =F29 -> 264398.53 | C30: =IF(A30<=$B$8,$B$13,$B$14) -> 4146.9798 | D30: =B30*$B$11 -> 991.49448 | E30: =C30-D30 -> 3155.4853 | F30: =B30-E30 -> 261243.04 | G30: =INT((A30-1)/12)+1 -> 1
A31: 13 | B31: =F30 -> 261243.04 | C31: =IF(A31<=$B$8,$B$13,$B$14) -> 4146.9798 | D31: =B31*$B$11 -> 979.66141 | E31: =C31-D31 -> 3167.3184 | F31: =B31-E31 -> 258075.72 | G31: =INT((A31-1)/12)+1 -> 2
... A102: 84 | B102: =F101 -> 4131.4867 | C102: =IF(A102<=$B$8,$B$13,$B$14) -> 4146.9798 | D102: =B102*$B$11 -> 15.493075 | E102: =C102-D102 -> 4131.4867 | F102: =B102-E102 -> -6.6547727e-09 | G102: =INT((A102-1)/12)+1 -> 7

Sheet PnL
A1: Profit & Loss - 4-Year Forecast (excl. VAT)
B3: Year 1 (ramp-up) | C3: Year 2 | D3: Year 3 | E3: Year 4
A4: Revenue | B4: =Revenue!$B$23 -> 789110.27 | C4: =Revenue!$E$13*(1+Assumptions!$B$31) -> 1090707.4 | D4: =C4*(1+Assumptions!$C$31) -> 1156149.8 | E4: =D4*(1+Assumptions!$D$31) -> 1202395.8 | F4: Y1 = ramped; Y2 = cruise speed + growth; then annual growth
A6: Food & beverage cost | B6: =B4*Assumptions!$B$34 -> 213059.77 | C6: =C4*Assumptions!$B$34 -> 294491 | D6: =D4*Assumptions!$B$34 -> 312160.46 | E6: =E4*Assumptions!$B$34 -> 324646.87
A7: Packaging | B7: =B4*Assumptions!$B$35 -> 7891.1027 | C7: =C4*Assumptions!$B$35 -> 10907.074 | D7: =D4*Assumptions!$B$35 -> 11561.498 | E7: =E4*Assumptions!$B$35 -> 12023.958
A8: Cleaning products | B8: =B4*Assumptions!$B$36 -> 7891.1027 | C8: =C4*Assumptions!$B$36 -> 10907.074 | D8: =D4*Assumptions!$B$36 -> 11561.498 | E8: =E4*Assumptions!$B$36 -> 12023.958
A9: Dishware renewal | B9: =B4*Assumptions!$B$37 -> 7891.1027 | C9: =C4*Assumptions!$B$37 -> 10907.074 | D9: =D4*Assumptions!$B$37 -> 11561.498 | E9: =E4*Assumptions!$B$37 -> 12023.958
A10: Total direct costs | B10: =SUM(B6:B9) -> 236733.08 | C10: =SUM(C6:C9) -> 327212.22 | D10: =SUM(D6:D9) -> 346844.95 | E10: =SUM(E6:E9) -> 360718.75
A11: Gross margin | B11: =B4-B10 -> 552377.19 | C11: =C4-C10 -> 763495.18 | D11: =D4-D10 -> 809304.89 | E11: =E4-E10 -> 841677.08
A12: Gross margin % | B12: =B11/B4 -> 0.7 | C12: =C11/C4 -> 0.7 | D12: =D11/D4 -> 0.7 | E12: =E11/E4 -> 0.7
A14: Rent & charges | B14: =Assumptions!$B$40 -> 60000 | C14: =Assumptions!$B$40 -> 60000 | D14: =Assumptions!$B$40 -> 60000 | E14: =Assumptions!$B$40 -> 60000 | F14: Held flat (3-6-9 lease)
A15: Energy | B15: =Assumptions!$B$41*1 -> 6000 | C15: =Assumptions!$B$41*(1+Assumptions!$B$50) -> 6120 | D15: =Assumptions!$B$41*(1+Assumptions!$B$50)^2 -> 6242.4 | E15: =Assumptions!$B$41*(1+Assumptions!$B$50)^3 -> 6367.248
A16: Maintenance | B16: =Assumptions!$B$42*1 -> 2000 | C16: =Assumptions!$B$42*(1+Assumptions!$B$50) -> 2040 | D16: =Assumptions!$B$42*(1+Assumptions!$B$50)^2 -> 2080.8 | E16: =Assumptions!$B$42*(1+Assumptions!$B$50)^3 -> 2122.416
A17: Marketing | B17: =Assumptions!$B$43*1 -> 18000 | C17: =Assumptions!$B$43*(1+Assumptions!$B$50) -> 18360 | D17: =Assumptions!$B$43*(1+Assumptions!$B$50)^2 -> 18727.2 | E17: =Assumptions!$B$43*(1+Assumptions!$B$50)^3 -> 19101.744
A18: Software & POS | B18: =Assumptions!$B$44*1 -> 2500 | C18: =Assumptions!$B$44*(1+Assumptions!$B$50) -> 2550 | D18: =Assumptions!$B$44*(1+Assumptions!$B$50)^2 -> 2601 | E18: =Assumptions!$B$44*(1+Assumptions!$B$50)^3 -> 2653.02
A19: Small equipment | B19: =Assumptions!$B$45*1 -> 3000 | C19: =Assumptions!$B$45*(1+Assumptions!$B$50) -> 3060 | D19: =Assumptions!$B$45*(1+Assumptions!$B$50)^2 -> 3121.2 | E19: =Assumptions!$B$45*(1+Assumptions!$B$50)^3 -> 3183.624
A20: Bank & insurance | B20: =Assumptions!$B$46*1 -> 3000 | C20: =Assumptions!$B$46*(1+Assumptions!$B$50) -> 3060 | D20: =Assumptions!$B$46*(1+Assumptions!$B$50)^2 -> 3121.2 | E20: =Assumptions!$B$46*(1+Assumptions!$B$50)^3 -> 3183.624
A21: Legal | B21: =Assumptions!$B$47*1 -> 2000 | C21: =Assumptions!$B$47*(1+Assumptions!$B$50) -> 2040 | D21: =Assumptions!$B$47*(1+Assumptions!$B$50)^2 -> 2080.8 | E21: =Assumptions!$B$47*(1+Assumptions!$B$50)^3 -> 2122.416
A22: Accounting | B22: =Assumptions!$B$48*1 -> 7200 | C22: =Assumptions!$B$48*(1+Assumptions!$B$50) -> 7344 | D22: =Assumptions!$B$48*(1+Assumptions!$B$50)^2 -> 7490.88 | E22: =Assumptions!$B$48*(1+Assumptions!$B$50)^3 -> 7640.6976
A23: Other costs | B23: =B4*Assumptions!$B$49 -> 7891.1027 | C23: =C4*Assumptions!$B$49 -> 10907.074 | D23: =D4*Assumptions!$B$49 -> 11561.498 | E23: =E4*Assumptions!$B$49 -> 12023.958
A24: Total operating costs | B24: =SUM(B14:B23) -> 111591.1 | C24: =SUM(C14:C23) -> 115481.07 | D24: =SUM(D14:D23) -> 117026.98 | E24: =SUM(E14:E23) -> 118398.75
A26: Gross salaries | B26: =Assumptions!$B$60*12*1 -> 250800 | C26: =Assumptions!$B$60*12*(1+Assumptions!$B$62) -> 255816 | D26: =Assumptions!$B$60*12*(1+Assumptions!$B$62)^2 -> 260932.32 | E26: =Assumptions!$B$60*12*(1+Assumptions!$B$62)^3 -> 266150.97 | F26: Roster held constant; wages grow with the wage-growth input
A27: Employer social charges | B27: =B26*Assumptions!$B$61 -> 105336 | C27: =C26*Assumptions!$B$61 -> 107442.72 | D27: =D26*Assumptions!$B$61 -> 109591.57 | E27: =E26*Assumptions!$B$61 -> 111783.41
A28: Payroll-based taxes | B28: =B26*Assumptions!$B$65 -> 3009.6 | C28: =C26*Assumptions!$B$65 -> 3069.792 | D28: =D26*Assumptions!$B$65 -> 3131.1878 | E28: =E26*Assumptions!$B$65 -> 3193.8116
A29: Total staff costs | B29: =SUM(B26:B28) -> 359145.6 | C29: =SUM(C26:C28) -> 366328.51 | D29: =SUM(D26:D28) -> 373655.08 | E29: =SUM(E26:E28) -> 381128.18
A31: EBITDA | B31: =B11-B24-B29 -> 81640.489 | C31: =C11-C24-C29 -> 281685.59 | D31: =D11-D24-D29 -> 318622.83 | E31: =E11-E24-E29 -> 342150.15
A32: EBITDA % | B32: =B31/B4 -> 0.10345891 | C32: =C31/C4 -> 0.25825954 | D32: =D31/D4 -> 0.27558956 | E32: =E31/E4 -> 0.284557
A33: Depreciation | B33: =Investment!$D$9 -> 35000 | C33: =Investment!$D$9 -> 35000 | D33: =Investment!$D$9 -> 35000 | E33: =Investment!$D$9 -> 35000
A34: Loan interest | B34: =SUMIFS(Loan!$D$19:$D$102,Loan!$G$19:$G$102,1) -> 12424.921 | C34: =SUMIFS(Loan!$D$19:$D$102,Loan!$G$19:$G$102,2) -> 10962.144 | D34: =SUMIFS(Loan!$D$19:$D$102,Loan!$G$19:$G$102,3) -> 9179.6042 | E34: =SUMIFS(Loan!$D$19:$D$102,Loan!$G$19:$G$102,4) -> 7315.1752 | F34: From the amortisation table - note the deferral effect in Year 1
A35: Profit before tax | B35: =B31-B33-B34 -> 34215.567 | C35: =C31-C33-C34 -> 235723.45 | D35: =D31-D33-D34 -> 274443.22 | E35: =E31-E33-E34 -> 299834.97
A36: Corporate tax | B36: =MAX(0,B35*Assumptions!$B$66) -> 8553.8918 | C36: =MAX(0,C35*Assumptions!$B$66) -> 58930.862 | D36: =MAX(0,D35*Assumptions!$B$66) -> 68610.805 | E36: =MAX(0,E35*Assumptions!$B$66) -> 74958.744
A37: NET INCOME | B37: =B35-B36 -> 25661.675 | C37: =C35-C36 -> 176792.58 | D37: =D35-D36 -> 205832.42 | E37: =E35-E36 -> 224876.23
A39: Cash flow (net income + depreciation) | B39: =B37+B33 -> 60661.675 | C39: =C37+C33 -> 211792.58 | D39: =D37+D33 -> 240832.42 | E39: =E37+E33 -> 259876.23
A40: Loan principal repaid | B40: =SUMIFS(Loan!$E$19:$E$102,Loan!$G$19:$G$102,1) -> 18756.958 | C40: =SUMIFS(Loan!$E$19:$E$102,Loan!$G$19:$G$102,2) -> 38801.614 | D40: =SUMIFS(Loan!$E$19:$E$102,Loan!$G$19:$G$102,3) -> 40584.154 | E40: =SUMIFS(Loan!$E$19:$E$102,Loan!$G$19:$G$102,4) -> 42448.583
A41: Free cash after debt service | B41: =B39-B40 -> 41904.718 | C41: =C39-C40 -> 172990.97 | D41: =D39-D40 -> 200248.26 | E41: =E39-E40 -> 217427.65

Sheet BreakEven
A1: Break-Even - 4 Rent Scenarios (Year 2 cruise-speed basis)
A3: SHARED INPUTS
A4: Contribution margin (1 − variable cost %) | B4: =1-(SUM(Assumptions!$B$34:$B$37)+Assumptions!$B$49) -> 0.69
A5: Annual fixed costs excl. rent | B5: =PnL!C29+PnL!C24-PnL!C14+PnL!C33+PnL!C34 -> 467771.73 | F5: Staff + operating costs (net of rent) + depreciation + interest, Year 2
A6: Average basket (excl. VAT, weighted) | B6: =Revenue!$E$13/(SUMPRODUCT(Assumptions!$B$8:$D$8,Assumptions!$B$19:$D$19)*Assumptions!$B$22*Assumptions!$B$23) -> 30.493752
A7: Planned covers / week (cruise speed) | B7: =SUMPRODUCT(Assumptions!$B$8:$D$8,Assumptions!$B$19:$D$19) -> 715.2
A9: SCENARIOS
B10: Scenario A | C10: Scenario B | D10: Scenario C | E10: Scenario D
A11: Monthly rent | B11: 3500 | C11: 5000 | D11: 6500 | E11: 8000
A12: Annual rent | B12: =B11*12 -> 42000 | C12: =C11*12 -> 60000 | D12: =D11*12 -> 78000 | E12: =E11*12 -> 96000
A13: Total annual fixed costs | B13: =$B$5+B12 -> 509771.73 | C13: =$B$5+C12 -> 527771.73 | D13: =$B$5+D12 -> 545771.73 | E13: =$B$5+E12 -> 563771.73
A14: Break-even revenue (excl. VAT) | B14: =B13/$B$4 -> 738799.61 | C14: =C13/$B$4 -> 764886.56 | D14: =D13/$B$4 -> 790973.52 | E14: =E13/$B$4 -> 817060.48
A15: Break-even revenue / month | B15: =B14/Assumptions!$B$23 -> 70361.867 | C15: =C14/Assumptions!$B$23 -> 72846.339 | D15: =D14/Assumptions!$B$23 -> 75330.812 | E15: =E14/Assumptions!$B$23 -> 77815.284
A16: Break-even covers / week | B16: =B14/$B$6/(Assumptions!$B$22*Assumptions!$B$23) -> 532.89125 | C16: =C14/$B$6/(Assumptions!$B$22*Assumptions!$B$23) -> 551.7076 | D16: =D14/$B$6/(Assumptions!$B$22*Assumptions!$B$23) -> 570.52395 | E16: =E14/$B$6/(Assumptions!$B$22*Assumptions!$B$23) -> 589.3403
A17: % of planned capacity | B17: =B16/$B$7 -> 0.74509403 | C17: =C16/$B$7 -> 0.77140324 | D17: =D16/$B$7 -> 0.79771246 | E17: =E16/$B$7 -> 0.82402167
A18: Reading: above ~85% of planned capacity, the location leaves no margin for error - walk away or renegotiate.
A19: Stress test: cut customers/day by 20% in Assumptions and watch this table before signing any lease.

Sheet KPIs
A1: KPI Dashboard - sanity checks
A3: KPI | B3: Value | C3: Benchmark low | D3: Benchmark high
A4: Revenue / year (cruise, excl. VAT) | B4: =Revenue!$E$13 -> 991552.18
A5: Revenue / seat | B5: =Revenue!$E$13/Assumptions!$B$69 -> 24788.804 | C5: 15000 | D5: 30000
A6: Revenue / m² | B6: =Revenue!$E$13/Assumptions!$B$70 -> 11017.246 | C6: 8000 | D6: 15000
A7: Revenue / opening hour (RevPAH) | B7: =Revenue!$E$13/(Assumptions!$B$71*Assumptions!$B$22*Assumptions!$B$23) -> 363.48553 | C7: 200 | D7: 500
A8: Food & beverage cost % | B8: =Assumptions!$B$34 -> 0.27 | C8: 0.25 | D8: 0.32
A9: Staff costs / revenue (Year 2) | B9: =PnL!C29/PnL!C4 -> 0.33586323 | C9: 0.3 | D9: 0.4
A10: Rent / revenue (Year 2) | B10: =PnL!C14/PnL!C4 -> 0.055010171 | C10: 0.06 | D10: 0.1 | E10: Above 10% at cruise speed is a red flag
A11: EBITDA margin (Year 2) | B11: =PnL!C31/PnL!C4 -> 0.25825954 | C11: 0.1 | D11: 0.2 | E11: If you are above the high benchmark, re-check your assumptions
A12: Total initial investment | B12: =Investment!$B$37 -> 607044.44
A13: Investment / annual revenue | B13: =Investment!$B$37/Revenue!$E$13 -> 0.61221634 | C13: 0.4 | D13: 0.8
A14: Payback (years, on Year-2 cash flow) | B14: =Investment!$B$37/PnL!C39 -> 2.8662214 | C14: 2.5 | D14: 4.5
A15: Break-even capacity use (Scenario B) | B15: =BreakEven!C17 -> 0.77140324 | D15: 0.85 | E15: Above 85%: no margin for error
A17: Benchmarks are broad French full-service-restaurant ranges - adjust to your segment.
